# Rust - 基础 - 错误处理


## 该章节包含以下内容
* 错误的分类
* 栈展开
* Result
* 总结

## 错误的分类

Rust 将错误组合成两个主要类别：可恢复错误（recoverable）和 不可恢复错误（unrecoverable）。可恢复错误通常代表向用户报告错误和重试操作是合理的情况，比如未找到文件。不可恢复错误通常是 bug 的同义词，比如尝试访问超过数组结尾的位置。

Rust 没有异常，不像大多数语言那样通过捕获异常来处理错误。

对于可恢复的错误，Rust 有 `Result<T, E>`， 通过这个枚举类型来处理错误情况。
对于不可恢复的错误，直接 `panic!` ，停止程序执行。

## 栈展开

当出现 panic 时，程序默认会开始 展开（unwinding），这意味着 Rust 会回溯栈并清理它遇到的每一个函数的数据，不过这个回溯并清理的过程有很多工作。另一种选择是直接 终止（abort），这会不清理数据就退出程序。那么程序所使用的内存需要由操作系统来清理。panic 时通过在 Cargo.toml 的 [profile] 部分增加 panic = 'abort'，可以由展开切换为终止。


## Result

Result 枚举，它定义有如下两个成员，Ok 和 Err：
```
enum Result<T, E> {
    Ok(T),
    Err(E),
}
```

当我们打开一个文件，我们需要判断文件是否存在，例如：

```
use std::fs::File;
fn main() {
    let f = File::open("t.txt"); // f 是 Result 枚举类型

    let f = match f {
        Ok(file) => file,
        Err(error) => {
            panic!("file not found error : {:?}", error); // panic! 输出错误信息并停止程序执行
        },
    };
}
```

如果文件不存在，我们就创建它，可以这样：
```
use std::fs::File;
use std::io::ErrorKind;
fn main() {
    let f = File::open("t.txt"); // f 是 Result 枚举类型

    let f = match f {
        Ok(file) => file,
        Err(error) =>  match error.kind() {    // 匹配错误
            ErrorKind::NotFound => match File::create("t.txt"){  // 创建文件
                Ok(new_file) => new_file,
                Err(e) => panic!("can not create file"),
            },
            other_error => panic!("other error"),
            //panic!("file not found error : {:?}", error); // panic! 输出错误信息并停止程序执行
        },
    };
}
```

### 失败时 panic 的简写：unwrap 和 expect

如果 Result 值是成员 Ok，unwrap 会返回 Ok 中的值。如果 Result 是成员 Err，unwrap 会为我们调用 panic! 

```
use std::fs::File;

fn main() {
    let f = File::open("hello.txt").unwrap();
    let f = File::open("hello.txt").expect("Failed to open hello.txt");
    println!("{:?}", f);
}
```

### 返回错误（抛出错误）

当编写一个其实现会调用一些可能会失败的操作的函数时，除了在这个函数中处理错误外，还可以选择让调用者知道这个错误并决定该如何处理。

类似于其他语言的抛出异常，让调用者去处理这些异常。

```
use std::io;
use std::io::Read;
use std::fs::File;

fn main() {
    let f = open_file();
    println!("{:?}", f);
}

// 返回错误 Result 泛型类型
fn open_file() -> Result<String, io::Error> {
    let f = File::open("t1.txt");

    let mut f = match f {
        Ok(file) => file,
        Err(err) => return Err(err),
    };

    let mut s = String::new();

    match f.read_to_string(&mut s) {
        Ok(_) => Ok(s),
        Err(e) => Err(e),
    }
}
输出：
Err(Os { code: 2, kind: NotFound, message: "No such file or directory" })
```

###  ? 抛出错误的简写

一个使用 ? 向调用者返回错误的函数

```
use std::io;
use std::io::Read;
use std::fs::File;

fn main() {
    let f = open_file();
    println!("{:?}", f);
}

fn open_file() -> Result<String, io::Error> {
    let mut f = File::open("t1.txt")? ;  // 返回错误的 简洁写法 ？
    let mut s = String::new();
    f.read_to_string(&mut s)? ;          // 返回错误的 简洁写法 ？
    Ok(s)
}
输出：
Err(Os { code: 2, kind: NotFound, message: "No such file or directory" })
```

File::open 调用结尾的 ? 将会把 Ok 中的值返回给变量 f。如果出现了错误，? 会提早返回整个函数并将一些 Err 值传播给调用者。同理也适用于 read_to_string 调用结尾的 ?。

问号运算符之后的链式方法调用，例如：
```
use std::io;
use std::io::Read;
use std::fs::File;

fn main() {
    let f = open_file();
    println!("{:?}", f);
}

fn open_file() -> Result<String, io::Error> {
    let mut s = String::new();
    File::open("t1.txt") ?.read_to_string(&mut s) ?  ;  // 返回错误的链式写法 ?. 
    Ok(s)
}
输出：
Err(Os { code: 2, kind: NotFound, message: "No such file or directory" })
```

`? 只能被用于返回类型为 Result 的函数`

## 总结

Rust 的错误处理功能被设计为帮助你编写更加健壮的代码。panic! 宏代表一个程序无法处理的状态，并停止执行而不是使用无效或不正确的值继续处理。Rust 类型系统的 Result 枚举代表操作可能会在一种可以恢复的情况下失败。可以使用 Result 来告诉代码调用者他需要处理潜在的成功或失败。在适当的场景使用 panic! 和 Result 将会使你的代码在面对不可避免的错误时显得更加可靠。